<?xml version="1.0" ?>
<!--
  Copyright 2024 DeepX, Inc. All rights reserved

  IC120 dumper truck model
-->
<sdf version="1.9">
    <model name='IC120_base'>
        <pose>0 0 0 0 0 0</pose>

        <link name="body_link">
            <visual name='visual'>
                <geometry>
                    <mesh>
                        <scale>1 1 1</scale>
                        <uri>./meshes/ic120-body.dae</uri>
                    </mesh>
                </geometry>
            </visual>
            <inertial>
                <mass>7000</mass>
                <inertia>
                    <ixx>2000</ixx>
                    <ixy>0</ixy>
                    <ixz>0</ixz>
                    <iyy>4000</iyy>
                    <iyz>0</iyz>
                    <izz>6000</izz>
                </inertia>
            </inertial>
        </link>

        <!-- left sprocket axis -->
        <joint name="left_sprocket_joint" type="fixed">
            <pose relative_to="body_link">2.35 1 0.65 0 0 0</pose>
            <parent>body_link</parent>
            <child>left_sprocket_link</child>
        </joint>
        
        <link name="left_sprocket_link"/>

        <!-- right sprocket axis -->
        <joint name="right_sprocket_joint" type="fixed">
            <pose relative_to="body_link">2.35 -1 0.65 0 0 0</pose>
            <parent>body_link</parent>
            <child>right_sprocket_link</child>
        </joint>
        
        <link name="right_sprocket_link"/>
        
        <!-- bucket axis -->
        <!-- Max dumping angle = 65° = 1.13446 rad -->
        <joint name="vessel_pin_joint" type="revolute">
            <pose relative_to="body_link">-3.0153 0 0.94605 0 0 0</pose>
            <parent>body_link</parent>
            <child>vessel_pin_link</child>
            <axis>
                <xyz>0 1 0</xyz>
                <limit>
                    <effort>1.0e8</effort>
                    <lower>-1.13446</lower>
                    <velocity>0.12</velocity>
                    <upper>0.0</upper>
                </limit>
            </axis>
        </joint>

        <link name="vessel_pin_link">
            <pose relative_to="vessel_pin_joint">0 0 0 0 0 0</pose>
            <visual name='visual'>
                <geometry>
                    <mesh>
                        <scale>1 1 1</scale>
                        <uri>./meshes/ic120-vessel.dae</uri>
                    </mesh>
                </geometry>
            </visual>
            <inertial>
                <mass>3000</mass>
                <inertia>
                    <ixx>2000</ixx>
                    <ixy>0</ixy>
                    <ixz>0</ixz>
                    <iyy>4000</iyy>
                    <iyz>0</iyz>
                    <izz>6000</izz>
                </inertia>
            </inertial>
        </link>
        
        <!-- cylinder outer axis -->
        <joint name="cylinder_head_joint" type="fixed">
            <pose relative_to="body_link">0.75792 0 0.73083 0 0 0</pose>
            <parent>body_link</parent>
            <child>cylinder_head_link</child>
        </joint>
        
        <!-- cylinder outer angle -->
        <link name="cylinder_head_link">
            <pose relative_to="cylinder_head_joint">0 0 0 0 0 0</pose>
            <visual name='visual'>
                <geometry>
                    <mesh>
                        <scale>1 1 1</scale>
                        <uri>./meshes/ic120-cylinder1.dae</uri>
                    </mesh>
                </geometry>
            </visual>
            <inertial>
                <mass>0.03</mass>
                <inertia>
                    <ixx>1.0</ixx>
                    <ixy>0</ixy>
                    <ixz>0</ixz>
                    <iyy>1.0</iyy>
                    <iyz>0</iyz>
                    <izz>1.0</izz>
                </inertia>
            </inertial>
        </link>
        
        <!-- cylinder inner prismatic joint -->
        <joint name="cylinder_rod_prismatic_joint" type="fixed">
            <pose relative_to="cylinder_head_joint">1.4989 0 0.51788 0 0 0</pose>
            <parent>cylinder_head_link</parent>
            <child>cylinder_rod_link</child>
        </joint>
        
        <!-- cylinder inner position -->
        <link name="cylinder_rod_link">
            <pose relative_to="cylinder_rod_prismatic_joint">0 0 0 0 0 0</pose>
            <visual name='visual'>
                <geometry>
                    <mesh>
                        <scale>1 1 1</scale>
                        <uri>./meshes/ic120-cylinder2.dae</uri>
                    </mesh>
                </geometry>
            </visual>
            <inertial>
                <mass>0.03</mass>
                <inertia>
                    <ixx>1.0</ixx>
                    <ixy>0</ixy>
                    <ixz>0</ixz>
                    <iyy>1.0</iyy>
                    <iyz>0</iyz>
                    <izz>1.0</izz>
                </inertia>
            </inertial>
        </link>

        <!-- TRACKS FOR LOCOMOTION -->
        <link name='left_track'>
            <pose>-0.4 1.0 0.55 0 0 0</pose>
            <gravity>1</gravity>
            <kinematic>0</kinematic>
            <!-- Debug visual -->
            <!--
            <visual name="left_track_visual">
            <pose>0 0 0 0 0 0</pose>
            <geometry>
               <box>
                  <size>4.5 0.69 1.0</size>
               </box>
            </geometry>
            <material>
               <ambient>1.0 0 0 1.0</ambient>
               <diffuse>1.0 0 0 1.0</diffuse>
               <specular>0.2 0.2 0.2 1.0</specular>
            </material>
            </visual>
            -->
            
            <collision name='left_track_collision'>
                <pose>0 0 0 0 0 0</pose>
                <geometry>
                    <box>
                        <size>4.5 0.69 1.0</size>
                    </box>
                </geometry>
                <surface>
                    <friction>
                    <ode>
                        <mu>0.7</mu>
                        <mu2>150</mu2>
                        <fdir1>0 1 0</fdir1>
                    </ode>
                    </friction>
                </surface>
            </collision>
            <inertial>
                <mass>2000</mass>
                <inertia>
                    <ixx>2000</ixx>
                    <ixy>0</ixy>
                    <ixz>0</ixz>
                    <iyy>4000</iyy>
                    <iyz>0</iyz>
                    <izz>6000</izz>
                </inertia>
            </inertial>
        </link>
      
        <link name='right_track'>
            <pose>-0.4 -1.0 0.55 0 0 0</pose>
            <gravity>1</gravity>
            <kinematic>0</kinematic>
            <!-- Debug visual -->
            <!--
            <visual name="right_track_visual">
                <pose>0 0 0 0 0 0</pose>
                <geometry>
                    <box>
                        <size>4.5 0.69 1.0</size>
                    </box>
                </geometry>
                <material>
                    <ambient>0 1.0 0 1.0</ambient>
                    <diffuse>0 1.0 0 1.0</diffuse>
                    <specular>0.2 0.2 0.2 1.0</specular>
                </material>
            </visual>
            -->

            <collision name='left_track_collision'>
                <pose>0 0 0 0 0 0</pose>
                <geometry>
                    <box>
                        <size>4.5 0.69 1.0</size>
                    </box>
                </geometry>
                <surface>
                    <friction>
                        <ode>
                            <mu>0.7</mu>
                            <mu2>150</mu2>
                            <fdir1>0 1 0</fdir1>
                        </ode>
                    </friction>
                </surface>
            </collision>
            <inertial>
                <mass>2000</mass>
                <inertia>
                    <ixx>2000</ixx>
                    <ixy>0</ixy>
                    <ixz>0</ixz>
                    <iyy>4000</iyy>
                    <iyz>0</iyz>
                    <izz>6000</izz>
                </inertia>
            </inertial>
        </link>

        <joint name='left_track_j' type='fixed'>
            <child>left_track</child>
            <parent>body_link</parent>
        </joint>
        <joint name='right_track_j' type='fixed'>
            <child>right_track</child>
            <parent>body_link</parent>
        </joint>

    </model>
</sdf>
