<?xml version="1.0" encoding="UTF-8"?>
<robot name="zx120">
  <joint name="world_joint" type="fixed">
    <origin xyz="0. 0. 0." rpy="0. 0. 0. "/>
    <parent link="world_link"/>
    <child link="caterpillar_link"/>
  </joint>
  <joint name="arm_cylinder_joint" type="continuous">
    <origin xyz="-1.0942609 0. 2.6658185" rpy="0. -1.2787697 0. "/>
    <parent link="boom_link"/>
    <child link="arm_cylinder_link"/>
    <axis xyz="0. 1. 0."/>
  </joint>
  <joint name="arm_joint" type="revolute">
    <origin xyz="0.0056535 0.0000031 4.6000023" rpy="0. -1.1837714 0. "/>
    <parent link="boom_link"/>
    <child link="arm_link"/>
    <axis xyz="0. 1. 0."/>
    <limit lower="-1.4235988" upper="0.705" effort="1e8" velocity="0.5"/>
  </joint>
  <joint name="arm_piston_joint" type="prismatic">
    <origin xyz="1.1360391 0.0000032 0.0000103" rpy="0. 0.0000016 0. "/>
    <parent link="arm_cylinder_link"/>
    <child link="arm_piston_link"/>
    <axis xyz="1. 0. 0."/>
    <limit lower="-10." upper="10." effort="1e8" velocity="0."/>
  </joint>
  <joint name="body_joint" type="revolute">
    <origin xyz="0.0000026 0.0000012 0.9999909" rpy="0. 0. 0."/>
    <parent link="caterpillar_link"/>
    <child link="body_link"/>
    <axis xyz="0. 0. 1."/>
    <limit lower="-3.14159265359" upper="3.14159265359" effort="1e8" velocity="0.2"/>
  </joint>
  <joint name="boom_cylinder_joint" type="continuous">
    <origin xyz="0.494531 -0.162387 0. " rpy="0. -1.274003 0. "/>
    <parent link="body_link"/>
    <child link="boom_cylinder_link"/>
    <axis xyz="0. 1. 0."/>
  </joint>
  <joint name="boom_joint" type="revolute">
    <origin xyz="0.14 -0.1644299 0.4240001" rpy="0. 1.045967 0. "/>
    <parent link="body_link"/>
    <child link="boom_link"/>
    <axis xyz="0. 1. 0."/>
    <limit lower="-0.6981315" upper="1.2915439" effort="1e8" velocity="0.6159937255"/>
  </joint>
  <joint name="boom_piston_joint" type="prismatic">
    <origin xyz="0.2 0. 0. " rpy="0. 0. 0."/>
    <parent link="boom_cylinder_link"/>
    <child link="boom_piston_link"/>
    <axis xyz="1. 0. 0."/>
    <limit lower="-10." upper="10." effort="1e8" velocity="0."/>
  </joint>
  <joint name="bucket_cylinder_joint" type="continuous">
    <origin xyz="0.4844949 -0.0000032 -0.5066893" rpy="1.8657556 0.0050742 1.5540968"/>
    <parent link="arm_link"/>
    <child link="bucket_cylinder_link"/>
    <axis xyz="1. 0. 0."/>
  </joint>
  <joint name="bucket_end_joint" type="fixed">
    <origin xyz="0. 0. 1.23" rpy="0. 0.8726646 0. "/>
    <parent link="bucket_link"/>
    <child link="bucket_end_link"/>
  </joint>
  <joint name="bucket_h_linkage_joint" type="continuous">
    <origin xyz="0.492806 0. -0.00206 " rpy="3.1415927 0.5415757 3.1415927"/>
    <parent link="bucket_side_linkage_link"/>
    <child link="bucket_h_linkage_link"/>
    <axis xyz="0. 1. 0."/>
  </joint>
  <joint name="bucket_joint" type="revolute">
    <origin xyz="-0.3747046 -0.0000032 -2.45944 " rpy="3.1415927 -0.5395223 3.1415927"/>
    <parent link="arm_link"/>
    <child link="bucket_link"/>
    <axis xyz="0. 1. 0."/>
    <limit lower="-0.1" upper="2.9717701" effort="1e8" velocity="0.5"/>
  </joint>
  <joint name="bucket_piston_joint" type="prismatic">
    <origin xyz="0. -0.256193 0. " rpy="0. 0. -1.5707964"/>
    <parent link="bucket_cylinder_link"/>
    <child link="bucket_piston_link"/>
    <axis xyz="1. 0. 0."/>
    <limit lower="-10." upper="10." effort="1e8" velocity="0."/>
  </joint>
  <joint name="bucket_side_linkage_joint" type="continuous">
    <origin xyz="-0.3174088 -0.0000032 -2.2056658" rpy="0. -0.6997983 0. "/>
    <parent link="arm_link"/>
    <child link="bucket_side_linkage_link"/>
    <axis xyz="0. 1. 0."/>
  </joint>
  <link name="world_link"/>
  <link name="arm_cylinder_link">
    <inertial>
      <origin xyz="0. 0. 0." rpy="0. 0. 0."/>
      <mass value="65.8099976"/>
      <inertia ixx="0.01" ixy="0." ixz="0." iyy="9.95" iyz="0." izz="9.95"/>
    </inertial>
    <visual>
      <origin xyz="0. 0. 0." rpy="0. 0. 0."/>
      <geometry>
        <mesh filename="package://zx120_description/meshes/bm_R_Cyl.dae" scale="1. 1. 1."/>
      </geometry>
    </visual>
    <collision>
      <origin xyz="0. 0. 0." rpy="0. 0. 0."/>
      <geometry>
        <mesh filename="package://zx120_description/meshes/bm_R_Cyl.dae" scale="1. 1. 1."/>
      </geometry>
    </collision>
  </link>
  <link name="arm_link">
    <inertial>
      <origin xyz="0. 0. 0." rpy="0. 0. 0."/>
      <mass value="480."/>
      <inertia ixx="14.24" ixy="0." ixz="31.36" iyy="319.92" iyz="0." izz="309.47"/>
    </inertial>
    <visual>
      <origin xyz="-0.0000033 -0.0000032 -0.0000078" rpy="0. 0.2950017 0. "/>
      <geometry>
        <mesh filename="package://zx120_description/meshes/arm_visual_geometry_arm.dae" scale="1. 1. 1."/>
      </geometry>
    </visual>
    <collision>
      <origin xyz="-0.0000033 -0.0000032 -0.0000078" rpy="0. 0.2950017 0. "/>
      <geometry>
        <mesh filename="package://zx120_description/meshes/arm_collision_geometry_arm.dae" scale="1. 1. 1."/>
      </geometry>
    </collision>
  </link>
  <link name="arm_piston_link">
    <inertial>
      <origin xyz="0. 0. 0." rpy="0. 0. 0."/>
      <mass value="48.1800003"/>
      <inertia ixx="0.01" ixy="0." ixz="0." iyy="9.83" iyz="0." izz="9.83"/>
    </inertial>
    <visual>
      <origin xyz="-0.0241023 -0.0000032 -0.0000103" rpy="0. -0.0000016 0. "/>
      <geometry>
        <mesh filename="package://zx120_description/meshes/bm_D_Cyl.dae" scale="1. 1. 1."/>
      </geometry>
    </visual>
    <collision>
      <origin xyz="-0.0241023 -0.0000032 -0.0000103" rpy="0. -0.0000016 0. "/>
      <geometry>
        <mesh filename="package://zx120_description/meshes/bm_D_Cyl.dae" scale="1. 1. 1."/>
      </geometry>
    </collision>
  </link>
  <link name="body_link">
    <inertial>
      <origin xyz="0. 0. 0." rpy="0. 0. 0."/>
      <mass value="5000."/>
      <inertia ixx="1." ixy="0." ixz="0." iyy="1." iyz="0." izz="1."/>
    </inertial>
    <visual>
      <origin xyz="0. 0. 0." rpy="0. 0. 0."/>
      <geometry>
        <mesh filename="package://zx120_description/meshes/bd_bm_R_Cyl_dm.dae" scale="1. 1. 1."/>
      </geometry>
    </visual>
    <visual>
      <origin xyz="0. 0. 0." rpy="0. 0. 0."/>
      <geometry>
        <mesh filename="package://zx120_description/meshes/R_lamp001.dae" scale="1. 1. 1."/>
      </geometry>
    </visual>
    <visual>
      <origin xyz="0. 0. 0." rpy="0. 0. 0."/>
      <geometry>
        <mesh filename="package://zx120_description/meshes/Y_lamp001.dae" scale="1. 1. 1."/>
      </geometry>
    </visual>
    <visual>
      <origin xyz="0. 0. 0." rpy="0. 0. 0."/>
      <geometry>
        <mesh filename="package://zx120_description/meshes/G_lamp.dae" scale="1. 1. 1."/>
      </geometry>
    </visual>
    <visual>
      <origin xyz="0. 0. 0." rpy="0. 0. 0."/>
      <geometry>
        <mesh filename="package://zx120_description/meshes/bake_body.dae" scale="1. 1. 1."/>
      </geometry>
    </visual>
    <collision>
      <origin xyz="0. 0. 0." rpy="0. 0. 0."/>
      <geometry>
        <mesh filename="package://zx120_description/meshes/bake_body.dae" scale="1. 1. 1."/>
      </geometry>
    </collision>
  </link>
  <link name="boom_cylinder_link">
    <inertial>
      <origin xyz="0. 0. 0." rpy="0. 0. 0."/>
      <mass value="131.6199951"/>
      <inertia ixx="9.216249" ixy="0." ixz="0." iyy="27.606432" iyz="0." izz="36.503907"/>
    </inertial>
    <visual>
      <origin xyz="0. 0. 0." rpy="0. 0. 0."/>
      <geometry>
        <mesh filename="package://zx120_description/meshes/bd_bm_R_Cyl_001.dae" scale="1. 1. 1."/>
      </geometry>
    </visual>
    <collision>
      <origin xyz="0. 0. 0." rpy="0. 0. 0."/>
      <geometry>
        <mesh filename="package://zx120_description/meshes/bd_bm_R_Cyl_001.dae" scale="1. 1. 1."/>
      </geometry>
    </collision>
  </link>
  <link name="boom_link">
    <inertial>
      <origin xyz="0. 0. 0." rpy="0. 0. 0."/>
      <mass value="1010."/>
      <inertia ixx="103.9" ixy="0." ixz="44.8" iyy="1574.1" iyz="0." izz="1489.6"/>
    </inertial>
    <visual>
      <origin xyz="0.0000001 -0.0000001 -0. " rpy="0. -1.1837697 0. "/>
      <geometry>
        <mesh filename="package://zx120_description/meshes/boom_visual_geometry_boom.dae" scale="1. 1. 1."/>
      </geometry>
    </visual>
    <collision>
      <origin xyz="0.0000001 -0.0000001 -0. " rpy="0. -1.1837697 0. "/>
      <geometry>
        <mesh filename="package://zx120_description/meshes/boom_collision_geometry_boom.dae" scale="1. 1. 1."/>
      </geometry>
    </collision>
  </link>
  <link name="boom_piston_link">
    <inertial>
      <origin xyz="0. 0. 0." rpy="0. 0. 0."/>
      <mass value="98.0056"/>
      <inertia ixx="6.6836" ixy="0." ixz="0." iyy="22.5995" iyz="0." izz="29.2292"/>
    </inertial>
    <visual>
      <origin xyz="0. 0. 0." rpy="0. 0. 0."/>
      <geometry>
        <mesh filename="package://zx120_description/meshes/bd_bm_D_Cyl_002.dae" scale="1. 1. 1."/>
      </geometry>
    </visual>
    <collision>
      <origin xyz="0. 0. 0." rpy="0. 0. 0."/>
      <geometry>
        <mesh filename="package://zx120_description/meshes/bd_bm_D_Cyl_002.dae" scale="1. 1. 1."/>
      </geometry>
    </collision>
  </link>
  <link name="bucket_cylinder_link">
    <inertial>
      <origin xyz="0. 0. 0." rpy="0. 0. 0."/>
      <mass value="65.8099976"/>
      <inertia ixx="0.01" ixy="0." ixz="0." iyy="9.95" iyz="0." izz="9.95"/>
    </inertial>
    <visual>
      <origin xyz="0. 0. 0." rpy="0. 0. -1.5707964"/>
      <geometry>
        <mesh filename="package://zx120_description/meshes/arm_R_Cyl.dae" scale="1. 1. 1."/>
      </geometry>
    </visual>
    <collision>
      <origin xyz="0. 0. 0." rpy="0. 0. -1.5707964"/>
      <geometry>
        <mesh filename="package://zx120_description/meshes/arm_R_Cyl.dae" scale="1. 1. 1."/>
      </geometry>
    </collision>
  </link>
  <link name="bucket_end_link">
    <inertial>
      <origin xyz="0. 0. 0." rpy="0. 0. 0."/>
      <mass value="0.001"/>
      <inertia ixx="1e-6" ixy="0." ixz="0." iyy="1e-6" iyz="0." izz="1e-6"/>
    </inertial>
  </link>
  <link name="bucket_h_linkage_link">
    <inertial>
      <origin xyz="0. 0. 0." rpy="0. 0. 0."/>
      <mass value="57.4500008"/>
      <inertia ixx="0.29" ixy="0." ixz="0." iyy="1.63" iyz="0." izz="1.88"/>
    </inertial>
    <visual>
      <origin xyz="0. 0. 0." rpy="0. 0. 0."/>
      <geometry>
        <mesh filename="package://zx120_description/meshes/arm_bk_C_2.dae" scale="1. 1. 1."/>
      </geometry>
    </visual>
    <collision>
      <origin xyz="0. 0. 0." rpy="0. 0. 0."/>
      <geometry>
        <mesh filename="package://zx120_description/meshes/arm_bk_C_2.dae" scale="1. 1. 1."/>
      </geometry>
    </collision>
  </link>
  <link name="bucket_link">
    <inertial>
      <origin xyz="0. 0. 0." rpy="0. 0. 0."/>
      <mass value="351.5"/>
      <inertia ixx="51.39" ixy="0." ixz="10.40" iyy="77.64" iyz="0." izz="91.99"/>
    </inertial>
    <visual>
      <origin xyz="0. 0. 0." rpy="0. 0. 0."/>
      <geometry>
        <mesh filename="package://zx120_description/meshes/bucket_visual_geometry_bk_C_dm.dae" scale="1. 1. 1."/>
      </geometry>
    </visual>
    <visual>
      <origin xyz="0. 0. 0." rpy="0. 0. 0."/>
      <geometry>
        <mesh filename="package://zx120_description/meshes/bucket_visual_geometry_arm_bk_dm.dae" scale="1. 1. 1."/>
      </geometry>
    </visual>
    <visual>
      <origin xyz="0. 0. 0." rpy="0. 0. 0."/>
      <geometry>
        <mesh filename="package://zx120_description/meshes/bucket_visual_geometry_backet.dae" scale="1. 1. 1."/>
      </geometry>
    </visual>
    <collision>
      <origin xyz="0. 0. 0." rpy="0. 0. 0."/>
      <geometry>
        <mesh filename="package://zx120_description/meshes/bucket_collision_geometry_bk_C_dm.dae" scale="1. 1. 1."/>
      </geometry>
    </collision>
    <collision>
      <origin xyz="0. 0. 0." rpy="0. 0. 0."/>
      <geometry>
        <mesh filename="package://zx120_description/meshes/bucket_collision_geometry_arm_bk_dm.dae" scale="1. 1. 1."/>
      </geometry>
    </collision>
    <collision>
      <origin xyz="0. 0. 0." rpy="0. 0. 0."/>
      <geometry>
        <mesh filename="package://zx120_description/meshes/bucket_collision_geometry_backet.dae" scale="1. 1. 1."/>
      </geometry>
    </collision>
  </link>
  <link name="bucket_piston_link">
    <inertial>
      <origin xyz="0. 0. 0." rpy="0. 0. 0."/>
      <mass value="48.1899986"/>
      <inertia ixx="0.01" ixy="0." ixz="0." iyy="9.83" iyz="0." izz="9.83"/>
    </inertial>
    <visual>
      <origin xyz="0. 0. 0." rpy="0. 0. 0."/>
      <geometry>
        <mesh filename="package://zx120_description/meshes/arm_D_Cyl_002.dae" scale="1. 1. 1."/>
      </geometry>
    </visual>
    <collision>
      <origin xyz="0. 0. 0." rpy="0. 0. 0."/>
      <geometry>
        <mesh filename="package://zx120_description/meshes/arm_D_Cyl_002.dae" scale="1. 1. 1."/>
      </geometry>
    </collision>
  </link>
  <link name="bucket_side_linkage_link">
    <inertial>
      <origin xyz="0. 0. 0." rpy="0. 0. 0."/>
      <mass value="16.3470993"/>
      <inertia ixx="0.2849" ixy="0." ixz="0." iyy="0.7623" iyz="0." izz="1.0241"/>
    </inertial>
    <visual>
      <origin xyz="0. 0. 0." rpy="0. 0. 0."/>
      <geometry>
        <mesh filename="package://zx120_description/meshes/arm_bk_C_1.dae" scale="1. 1. 1."/>
      </geometry>
    </visual>
    <visual>
      <origin xyz="0. 0. 0." rpy="0. 0. 0."/>
      <geometry>
        <mesh filename="package://zx120_description/meshes/arm_C_bk_dm.dae" scale="1. 1. 1."/>
      </geometry>
    </visual>
    <visual>
      <origin xyz="0. 0. 0." rpy="0. 0. 0."/>
      <geometry>
        <mesh filename="package://zx120_description/meshes/arm_C_dm.dae" scale="1. 1. 1."/>
      </geometry>
    </visual>
     <collision>
      <origin xyz="0. 0. 0." rpy="0. 0. 0."/>
      <geometry>
        <mesh filename="package://zx120_description/meshes/arm_bk_C_1.dae" scale="1. 1. 1."/>
      </geometry>
    </collision>
    <collision>
      <origin xyz="0. 0. 0." rpy="0. 0. 0."/>
      <geometry>
        <mesh filename="package://zx120_description/meshes/arm_C_bk_dm.dae" scale="1. 1. 1."/>
      </geometry>
    </collision>
    <collision>
      <origin xyz="0. 0. 0." rpy="0. 0. 0."/>
      <geometry>
        <mesh filename="package://zx120_description/meshes/arm_C_dm.dae" scale="1. 1. 1."/>
      </geometry>
    </collision>
  </link>
  <link name="caterpillar_link">
    <inertial>
      <origin xyz="0. 0. 0." rpy="0. 0. 0."/>
      <mass value="50000."/>
      <inertia ixx="1." ixy="0." ixz="0." iyy="1." iyz="0." izz="1."/>
    </inertial>
    <visual>
      <origin xyz="0.0000026 0.0000012 -0.000009 " rpy="0. 0. 0."/>
      <geometry>
        <mesh filename="package://zx120_description/meshes/bake_body_001.dae" scale="1. 1. 1."/>
      </geometry>
    </visual>
    <collision>
      <origin xyz="0.0000026 0.0000012 -0.000009 " rpy="0. 0. 0."/>
      <geometry>
        <mesh filename="package://zx120_description/meshes/bake_body_001.dae" scale="1. 1. 1."/>
      </geometry>
    </collision>
  </link>
</robot>
